Workbook
Name Slicer_Order_Date: #N/A
Name Slicer_Payment_Method: #N/A
Name Slicer_Quantity: #N/A
Name Slicer_Status: #N/A
Name Total_Revenue: Table1[[#Headers],[Total ]]

Sheet Pivot Tables
C2: Broducts Revenue | M2: Top Selling Category
C3: Broduct | D3: Sum of Total | E3: KPIS | F3: ="Top Selling Product = "&INDEX(C3:C8,MATCH(MAX(D3:D8),D3:D8,0)) -> Top Selling Product = shoes | M3: Category | N3: Sum of Quantity | O3: Sum of Total
C4: Comics | D4: 6629.68 | M4: Books | N4: 74 | O4: 13156.47 | P4: KPIS | Q4: ="Top Selling Category = "&INDEX(M4:M8,MATCH(MAX(O4:O8),O4:O8,0)) -> Top Selling Category = Clothings
C5: Basketball | D5: 6666.48 | M5: Clothings | N5: 57 | O5: 32475.08
C6: Jeans | D6: 6674.67 | M6: Electronics | N6: 25 | O6: 4587.15
C7: Lamp | D7: 8069.73 | M7: Home | N7: 69 | O7: 21416.28
C8: shoes | D8: 18219 | M8: Sports | N8: 52 | O8: 16130.89
M11: Orders By Bayment Method
M12: Bayment Method | N12: Count of Order_ID | O12: KPIS | P12: ="Most Used Payment Method = "&INDEX(M13:M16,MATCH(MAX(N13:N16),N13:N16,0)) -> Most Used Payment Method = Cash on Delivery
C13: Sum of Total | D13: Count of Order_ID | E13: Sum of Quantity | F13: KPIS | G13: ="AOV = "&ROUND(GETPIVOTDATA("Sum of Total ",$C$13)/GETPIVOTDATA("Count of Order_ID",$C$13),2) -> AOV = 964.46 | M13: Bank Transfer | N13: 20
A14: Bayment Method By Revenue | C14: 87765.87 | D14: 91 | E14: 277 | M14: Cash on Delivery | N14: 30
A15: Bayment Method | B15: Sum of Total | M15: Credit Card | N15: 21
A16: Cash on Delivery | B16: 20640.58 | C16: KPIS | D16: ="Top Revenue by Bayment Method = "&INDEX(A16:A19,MATCH(MAX(B16:B19),B16:B19,0)) -> Top Revenue by Bayment Method = Bank Transfer | M16: PayPal | N16: 20
A17: Credit Card | B17: 20877.39
A18: PayPal | B18: 23122.74 | J18: Sales Date | M18: Product Quantity
A19: Bank Transfer | B19: 23125.16 | J19: Date | K19: Sum of Total | M19: Product | N19: Sum of Quantity | O19: KPIS | P19: ="Highiest Quantity Product = "&INDEX(M20:M24,MATCH(MAX(N20:N24),N20:N24,)) -> Highiest Quantity Product = shoes
J20: 2023 | K20: 1532.04 | M20: shoes | N20: 28
A21: Orders Status | J21: Jan | K21: 1532.04 | M21: Science | N21: 24
A22: Status | B22: Count of Order_ID | J22: May | K22: 0 | M22: Blender | N22: 23
A23: Cancelled | B23: 0.15384615 | J23: 2024 | K23: 15011.61 | M23: Lamp | N23: 23
A24: Delivered | B24: 0.10989011 | J24: Nov | K24: 7820.32 | M24: Comics | N24: 20
A25: Processing | B25: 0.24175824 | J25: Dec | K25: 7191.29
A26: Returned | B26: 0.26373626 | J26: 2025 | K26: 71222.22
A27: Shipped | B27: 0.23076923 | J27: Jan | K27: 7090.35
A28: Grand Total | B28: 1 | J28: Feb | K28: 9401.57
J29: Mar | K29: 5470.36
J30: Apr | K30: 1200.28
A31: Revenue By Orders Status | J31: May | K31: 5579.26
A32: Status | B32: Sum of Total | J32: Jun | K32: 4700.23
A33: Cancelled | B33: 0 | J33: Jul | K33: 10538.27
A34: Delivered | B34: 0.18161376 | J34: Aug | K34: 3335.06
A35: Processing | B35: 0.35873854 | J35: Sep | K35: 2606.01
A36: Returned | B36: 0 | J36: Oct | K36: 20200.43
A37: Shipped | B37: 0.4596477 | J37: Nov | K37: 1100.4
D41: Count of Order_ID | E41: Count of Customer_Name
D42: 91 | E42: 91

Sheet Dashboard

Sheet Pivot 2
A1: Status | B1: Returned
A3: Orders | B3: Sum of Total
A4: Electronics | B4: 0
A5: Books | B5: 0
A6: Home | B6: 0
A7: Clothings | B7: 0
A8: Sports | B8: 0
A9: Grand Total | B9: 0

Sheet Pivot 3
A1: Status | B1: (All)
A3: Orders | B3: Sum of Total
A4: Electronics | B4: 4587.15
A5: Books | B5: 13156.47
A6: Sports | B6: 16130.89
A7: Home | B7: 21416.28
A8: Clothings | B8: 32475.08
A9: Grand Total | B9: 87765.87

Sheet Pivot 4
A1: Status | B1: (All)
A3: Orders | B3: Sum of Total
A4: Books | B4: 13156.47
A5: Clothings | B5: 32475.08
A6: Electronics | B6: 4587.15
A7: Home | B7: 21416.28
A8: Sports | B8: 16130.89
A9: Grand Total | B9: 87765.87

Sheet Pivot 5
A1: Status | B1: (All)
A3: Orders | B3: Sum of Total
A4: Books | B4: 13156.47
A5: Clothings | B5: 32475.08
A6: Electronics | B6: 4587.15
A7: Home | B7: 21416.28
A8: Sports | B8: 16130.89
A9: Grand Total | B9: 87765.87

Sheet Pivot 6
A1: Status | B1: (All)
A3: Orders | B3: Sum of Total
A4: Books | B4: 13156.47
A5: Clothings | B5: 32475.08
A6: Electronics | B6: 4587.15
A7: Home | B7: 21416.28
A8: Sports | B8: 16130.89
A9: Grand Total | B9: 87765.87

Sheet E-Commerce sales
A1: ID | B1: Customer_Name | C1: Order_ID | D1: Order_Date | E1: Product | F1: Category | G1: Quantity | H1: Quality Check | I1: Quantity_Check2 | J1: Price | K1: Price Check 1 | L1: Price Check 2 | M1: Payment_Method | N1: Status | O1: Total | P1: Total_Check
A2: 155 | B2: Customer_155 | C2: ORD-20182 | D2: 45778 | E2: shoes | F2: =VLOOKUP(E2,Mapping!$A$1:$B$20,2,FALSE) -> Clothings | G2: 1 | H2: =IF(AND(G2<0,G2<>$N$4),"ERORR","OK") -> OK | I2: =ISNUMBER(G2) -> TRUE | J2: 523 | K2: =IF(OR(Table1[[#This Row],[Price]]>$S$20,Table1[[#This Row],[Price]]<$T$19),"Outlier","OK") -> OK | L2: =ISNUMBER(J2) -> TRUE | M2: PayPal | N2: Returned | O2: 0 | P2: =IF(AND(O2<0,O2<>N17),"ERORR","OK") -> OK
A3: 177 | B3: Customer_177 | C3: ORD-64136 | D3: 45866 | E3: Laptop | F3: =VLOOKUP(E3,Mapping!$A$1:$B$20,2,FALSE) -> Electronics | G3: 1 | H3: =IF(AND(G3<0,G3<>$N$4),"ERORR","OK") -> OK | I3: =ISNUMBER(G3) -> TRUE | J3: =MEDIAN(J26:J79) -> 569.19 | K3: =IF(OR(Table1[[#This Row],[Price]]>$S$20,Table1[[#This Row],[Price]]<$T$19),"Outlier","OK") -> OK | L3: =ISNUMBER(J3) -> TRUE | M3: Bank Transfer | N3: Returned | O3: 0 | P3: =IF(AND(O3<0,O3<>N18),"ERORR","OK") -> OK
A4: 175 | B4: Customer_175 | C4: ORD-56651 | D4: 45712 | E4: Headphones | F4: =VLOOKUP(E4,Mapping!$A$1:$B$20,2,FALSE) -> Electronics | G4: 1 | H4: =IF(AND(G4<0,G4<>$N$4),"ERORR","OK") -> OK | I4: =ISNUMBER(G4) -> TRUE | J4: 111.36 | K4: =IF(OR(Table1[[#This Row],[Price]]>$S$20,Table1[[#This Row],[Price]]<$T$19),"Outlier","OK") -> OK | L4: =ISNUMBER(J4) -> TRUE | M4: Credit Card | N4: Processing | O4: =Table1[[#This Row],[Price]]*Table1[[#This Row],[Quantity]] -> 111.36 | P4: =IF(AND(O4<0,O4<>N19),"ERORR","OK") -> OK
A5: 100 | B5: Customer_100 | C5: ORD-41285 | D5: 45618 | E5: Blender | F5: =VLOOKUP(E5,Mapping!$A$1:$B$20,2,FALSE) -> Home | G5: 3 | H5: =IF(AND(G5<0,G5<>$N$4),"ERORR","OK") -> OK | I5: =ISNUMBER(G5) -> TRUE | J5: 438 | K5: =IF(OR(Table1[[#This Row],[Price]]>$S$20,Table1[[#This Row],[Price]]<$T$19),"Outlier","OK") -> OK | L5: =ISNUMBER(J5) -> TRUE | M5: Cash on Delivery | N5: Shipped | O5: =Table1[[#This Row],[Price]]*Table1[[#This Row],[Quantity]] -> 1314 | P5: =IF(AND(O5<0,O5<>N20),"ERORR","OK") -> OK
A6: 197 | B6: Customer_197 | C6: ORD-79139 | D6: 45831 | E6: Blender | F6: =VLOOKUP(E6,Mapping!$A$1:$B$20,2,FALSE) -> Home | G6: 1 | H6: =IF(AND(G6<0,G6<>$N$4),"ERORR","OK") -> OK | I6: =ISNUMBER(G6) -> TRUE | J6: 545 | K6: =IF(OR(Table1[[#This Row],[Price]]>$S$20,Table1[[#This Row],[Price]]<$T$19),"Outlier","OK") -> OK | L6: =ISNUMBER(J6) -> TRUE | M6: PayPal | N6: Cancelled | O6: 0 | P6: =IF(AND(O6<0,O6<>N22),"ERORR","OK") -> OK | S6: ="Total Revenue = "&SUM(Table1[[Total ]]) -> Total Revenue = 82032.115
A7: 150 | B7: Customer_150 | C7: ORD-76902 | D7: 45623 | E7: Yoga Mat | F7: =VLOOKUP(E7,Mapping!$A$1:$B$20,2,FALSE) -> Sports | G7: 1 | H7: =IF(AND(G7<0,G7<>$N$4),"ERORR","OK") -> OK | I7: =ISNUMBER(G7) -> TRUE | J7: 206.19 | K7: =IF(OR(Table1[[#This Row],[Price]]>$S$20,Table1[[#This Row],[Price]]<$T$19),"Outlier","OK") -> OK | L7: =ISNUMBER(J7) -> TRUE | M7: Credit Card | N7: Returned | O7: 0 | P7: =IF(AND(O7<0,O7<>N22),"ERORR","OK") -> OK | S7: ="Total Order = "&COUNTA(Table1[Order_ID]) -> Total Order = 88
A8: 181 | B8: Customer_181 | C8: ORD-54481 | D8: 45655 | E8: Smartphone | F8: =VLOOKUP(E8,Mapping!$A$1:$B$20,2,FALSE) -> Electronics | G8: 1 | H8: =IF(AND(G8<0,G8<>$N$4),"ERORR","OK") -> OK | I8: =ISNUMBER(G8) -> TRUE | J8: 266.48 | K8: =IF(OR(Table1[[#This Row],[Price]]>$S$20,Table1[[#This Row],[Price]]<$T$19),"Outlier","OK") -> OK | L8: =ISNUMBER(J8) -> TRUE | M8: Cash on Delivery | N8: Cancelled | O8: 0 | P8: =IF(AND(O8<0,O8<>N23),"ERORR","OK") -> OK | S8: ="(AOV) = "&SUM(O:O)/COUNTA(D:D) -> (AOV) = 921.709157303371
A9: 132 | B9: Customer_132 | C9: ORD-40186 | D9: 45749 | E9: Yoga Mat | F9: =VLOOKUP(E9,Mapping!$A$1:$B$20,2,FALSE) -> Sports | G9: 1 | H9: =IF(AND(G9<0,G9<>$N$4),"ERORR","OK") -> OK | I9: =ISNUMBER(G9) -> TRUE | J9: 266.7 | K9: =IF(OR(Table1[[#This Row],[Price]]>$S$20,Table1[[#This Row],[Price]]<$T$19),"Outlier","OK") -> OK | L9: =ISNUMBER(J9) -> TRUE | M9: PayPal | N9: Delivered | O9: =Table1[[#This Row],[Price]]*Table1[[#This Row],[Quantity]] -> 266.7 | P9: =IF(AND(O9<0,O9<>N25),"ERORR","OK") -> OK | S9: ="Total Quantity Sold = "&SUM(G:G) -> Total Quantity Sold = 269
A10: 168 | B10: Customer_168 | C10: ORD-53430 | D10: 45965 | E10: Biography | F10: =VLOOKUP(E10,Mapping!$A$1:$B$20,2,FALSE) -> Books | G10: 2 | H10: =IF(AND(G10<0,G10<>$N$4),"ERORR","OK") -> OK | I10: =ISNUMBER(G10) -> TRUE | J10: 141.49 | K10: =IF(OR(Table1[[#This Row],[Price]]>$S$20,Table1[[#This Row],[Price]]<$T$19),"Outlier","OK") -> OK | L10: =ISNUMBER(J10) -> TRUE | M10: PayPal | N10: Cancelled | O10: 0 | P10: =IF(AND(O10<0,O10<>N27),"ERORR","OK") -> OK | S10: ="Unique Costomers = "&COUNTA(Mapping!D:D) -> Unique Costomers = 93
A11: 137 | B11: Customer_137 | C11: ORD-91254 | D11: 45711 | E11: Vacuum | F11: =VLOOKUP(E11,Mapping!$A$1:$B$20,2,FALSE) -> Home | G11: 3 | H11: =IF(AND(G11<0,G11<>$N$4),"ERORR","OK") -> OK | I11: =ISNUMBER(G11) -> TRUE | J11: =MEDIAN(J46:J94) -> 649.005 | K11: =IF(OR(Table1[[#This Row],[Price]]>$S$20,Table1[[#This Row],[Price]]<$T$19),"Outlier","OK") -> OK | L11: =ISNUMBER(J11) -> TRUE | M11: Cash on Delivery | N11: Delivered | O11: =Table1[[#This Row],[Price]]*Table1[[#This Row],[Quantity]] -> 1947.015 | P11: =IF(AND(O11<0,O11<>N28),"ERORR","OK") -> OK
A12: 162 | B12: Customer_162 | C12: ORD-27743 | D12: 45796 | E12: Blender | F12: =VLOOKUP(E12,Mapping!$A$1:$B$20,2,FALSE) -> Home | G12: 2 | H12: =IF(AND(G12<0,G12<>$N$4),"ERORR","OK") -> OK | I12: =ISNUMBER(G12) -> TRUE | J12: 553 | K12: =IF(OR(Table1[[#This Row],[Price]]>$S$20,Table1[[#This Row],[Price]]<$T$19),"Outlier","OK") -> OK | L12: =ISNUMBER(J12) -> TRUE | M12: Credit Card | N12: Returned | O12: 0 | P12: =IF(AND(O12<0,O12<>N28),"ERORR","OK") -> OK
A13: 186 | B13: Customer_186 | C13: ORD-90569 | D13: 45936 | E13: Laptop | F13: =VLOOKUP(E13,Mapping!$A$1:$B$20,2,FALSE) -> Electronics | G13: 1 | H13: =IF(AND(G13<0,G13<>$N$4),"ERORR","OK") -> OK | I13: =ISNUMBER(G13) -> TRUE | J13: 365.34 | K13: =IF(OR(Table1[[#This Row],[Price]]>$S$20,Table1[[#This Row],[Price]]<$T$19),"Outlier","OK") -> OK | L13: =ISNUMBER(J13) -> TRUE | M13: Bank Transfer | N13: Delivered | O13: =Table1[[#This Row],[Price]]*Table1[[#This Row],[Quantity]] -> 365.34 | P13: =IF(AND(O13<0,O13<>N30),"ERORR","OK") -> OK
A14: 105 | B14: Customer_105 | C14: ORD-22442 | D14: 45616 | E14: Tennis Racket | F14: =VLOOKUP(E14,Mapping!$A$1:$B$20,2,FALSE) -> Sports | G14: 3 | H14: =IF(AND(G14<0,G14<>$N$4),"ERORR","OK") -> OK | I14: =ISNUMBER(G14) -> TRUE | J14: =MEDIAN(J17:J69) -> 546.04 | K14: =IF(OR(Table1[[#This Row],[Price]]>$S$20,Table1[[#This Row],[Price]]<$T$19),"Outlier","OK") -> OK | L14: =ISNUMBER(J14) -> TRUE | M14: Cash on Delivery | N14: Cancelled | O14: 0 | P14: =IF(AND(O14<0,O14<>N29),"ERORR","OK") -> OK
A15: 102 | B15: Customer_102 | C15: ORD-84355 | D15: 45649 | E15: Tennis Racket | F15: =VLOOKUP(E15,Mapping!$A$1:$B$20,2,FALSE) -> Sports | G15: 1 | H15: =IF(AND(G15<0,G15<>$N$4),"ERORR","OK") -> OK | I15: =ISNUMBER(G15) -> TRUE | J15: 389.05 | K15: =IF(OR(Table1[[#This Row],[Price]]>$S$20,Table1[[#This Row],[Price]]<$T$19),"Outlier","OK") -> OK | L15: =ISNUMBER(J15) -> TRUE | M15: PayPal | N15: Delivered | O15: =Table1[[#This Row],[Price]]*Table1[[#This Row],[Quantity]] -> 389.05 | P15: =IF(AND(O15<0,O15<>N30),"ERORR","OK") -> OK
A16: 184 | B16: Customer_184 | C16: ORD-67799 | D16: 45703 | E16: Jeans | F16: =VLOOKUP(E16,Mapping!$A$1:$B$20,2,FALSE) -> Clothings | G16: 4 | H16: =IF(AND(G16<0,G16<>$N$4),"ERORR","OK") -> OK | I16: =ISNUMBER(G16) -> TRUE | J16: =MEDIAN(J82) -> 741.63 | K16: =IF(OR(Table1[[#This Row],[Price]]>$S$20,Table1[[#This Row],[Price]]<$T$19),"Outlier","OK") -> OK | L16: =ISNUMBER(J16) -> TRUE | M16: Bank Transfer | N16: Processing | O16: =Table1[[#This Row],[Price]]*Table1[[#This Row],[Quantity]] -> 2966.52 | P16: =IF(AND(O16<0,O16<>N33),"ERORR","OK") -> OK | R16: Q1 | S16: =_xlfn.QUARTILE.INC(J:J,1) -> 408.8575
A17: 113 | B17: Customer_113 | C17: ORD-23994 | D17: 45862 | E17: Fiction | F17: =VLOOKUP(E17,Mapping!$A$1:$B$20,2,FALSE) -> Books | G17: 1 | H17: =IF(AND(G17<0,G17<>$N$4),"ERORR","OK") -> OK | I17: =ISNUMBER(G17) -> TRUE | J17: 411.81 | K17: =IF(OR(Table1[[#This Row],[Price]]>$S$20,Table1[[#This Row],[Price]]<$T$19),"Outlier","OK") -> OK | L17: =ISNUMBER(J17) -> TRUE | M17: Credit Card | N17: Processing | O17: =Table1[[#This Row],[Price]]*Table1[[#This Row],[Quantity]] -> 411.81 | P17: =IF(AND(O17<0,O17<>N33),"ERORR","OK") -> OK | R17: q3 | S17: =_xlfn.QUARTILE.INC(J:J,3) -> 741.63
A18: 159 | B18: Customer_159 | C18: ORD-98162 | D18: 45866 | E18: Microwave | F18: =VLOOKUP(E18,Mapping!$A$1:$B$20,2,FALSE) -> Home | G18: 3 | H18: =IF(AND(G18<0,G18<>$N$4),"ERORR","OK") -> OK | I18: =ISNUMBER(G18) -> TRUE | J18: 163.16 | K18: =IF(OR(Table1[[#This Row],[Price]]>$S$20,Table1[[#This Row],[Price]]<$T$19),"Outlier","OK") -> OK | L18: =ISNUMBER(J18) -> TRUE | M18: PayPal | N18: Shipped | O18: =Table1[[#This Row],[Price]]*Table1[[#This Row],[Quantity]] -> 489.48 | P18: =IF(AND(O18<0,O18<>N34),"ERORR","OK") -> OK | R18: IQR | S18: =S17-S16 -> 332.7725
A19: 138 | B19: Customer_138 | C19: ORD-34319 | D19: 45878 | E19: Lamp | F19: =VLOOKUP(E19,Mapping!$A$1:$B$20,2,FALSE) -> Home | G19: 1 | H19: =IF(AND(G19<0,G19<>$N$4),"ERORR","OK") -> OK | I19: =ISNUMBER(G19) -> TRUE | J19: 531.06 | K19: =IF(OR(Table1[[#This Row],[Price]]>$S$20,Table1[[#This Row],[Price]]<$T$19),"Outlier","OK") -> OK | L19: =ISNUMBER(J19) -> TRUE | M19: PayPal | N19: Processing | O19: =Table1[[#This Row],[Price]]*Table1[[#This Row],[Quantity]] -> 531.06 | P19: =IF(AND(O19<0,O19<>N36),"ERORR","OK") -> OK | R19: Lower | S19: =S16-(1.5*S18) -> -90.30125 | T19: =ABS(S19) -> 90.30125
A20: 104 | B20: Customer_104 | C20: ORD-93614 | D20: 45950 | E20: Biography | F20: =VLOOKUP(E20,Mapping!$A$1:$B$20,2,FALSE) -> Books | G20: 1 | H20: =IF(AND(G20<0,G20<>$N$4),"ERORR","OK") -> OK | I20: =ISNUMBER(G20) -> TRUE | J20: 552.51 | K20: =IF(OR(Table1[[#This Row],[Price]]>$S$20,Table1[[#This Row],[Price]]<$T$19),"Outlier","OK") -> OK | L20: =ISNUMBER(J20) -> TRUE | M20: Cash on Delivery | N20: Processing | O20: =Table1[[#This Row],[Price]]*Table1[[#This Row],[Quantity]] -> 552.51 | P20: =IF(AND(O20<0,O20<>N37),"ERORR","OK") -> OK | R20: Upper | S20: =S17+1.5*S18 -> 1240.7887
A21: 169 | B21: Customer_169 | C21: ORD-75539 | D21: 45881 | E21: Basketball | F21: =VLOOKUP(E21,Mapping!$A$1:$B$20,2,FALSE) -> Sports | G21: 1 | H21: =IF(AND(G21<0,G21<>$N$4),"ERORR","OK") -> OK | I21: =ISNUMBER(G21) -> TRUE | J21: 582.13 | K21: =IF(OR(Table1[[#This Row],[Price]]>$S$20,Table1[[#This Row],[Price]]<$T$19),"Outlier","OK") -> OK | L21: =ISNUMBER(J21) -> TRUE | M21: Credit Card | N21: Returned | O21: 0 | P21: =IF(AND(O21<0,O21<>N38),"ERORR","OK") -> OK
A22: 108 | B22: Customer_108 | C22: ORD-64400 | D22: 45953 | E22: Science | F22: =VLOOKUP(E22,Mapping!$A$1:$B$20,2,FALSE) -> Books | G22: 1 | H22: =IF(AND(G22<0,G22<>$N$4),"ERORR","OK") -> OK | I22: =ISNUMBER(G22) -> TRUE | J22: 600.29 | K22: =IF(OR(Table1[[#This Row],[Price]]>$S$20,Table1[[#This Row],[Price]]<$T$19),"Outlier","OK") -> OK | L22: =ISNUMBER(J22) -> TRUE | M22: Cash on Delivery | N22: Processing | O22: =Table1[[#This Row],[Price]]*Table1[[#This Row],[Quantity]] -> 600.29 | P22: =IF(AND(O22<0,O22<>N39),"ERORR","OK") -> OK
A23: 151 | B23: Customer_151 | C23: ORD-56552 | D23: 45839 | E23: Comics | F23: =VLOOKUP(E23,Mapping!$A$1:$B$20,2,FALSE) -> Books | G23: 2 | H23: =IF(AND(G23<0,G23<>$N$4),"ERORR","OK") -> OK | I23: =ISNUMBER(G23) -> TRUE | J23: 457.16 | K23: =IF(OR(Table1[[#This Row],[Price]]>$S$20,Table1[[#This Row],[Price]]<$T$19),"Outlier","OK") -> OK | L23: =ISNUMBER(J23) -> TRUE | M23: PayPal | N23: Processing | O23: =Table1[[#This Row],[Price]]*Table1[[#This Row],[Quantity]] -> 914.32 | P23: =IF(AND(O23<0,O23<>N39),"ERORR","OK") -> OK
A24: 148 | B24: Customer_148 | C24: ORD-38423 | D24: 45729 | E24: Tennis Racket | F24: =VLOOKUP(E24,Mapping!$A$1:$B$20,2,FALSE) -> Sports | G24: 1 | H24: =IF(AND(G24<0,G24<>$N$4),"ERORR","OK") -> OK | I24: =ISNUMBER(G24) -> TRUE | J24: 660.98 | K24: =IF(OR(Table1[[#This Row],[Price]]>$S$20,Table1[[#This Row],[Price]]<$T$19),"Outlier","OK") -> OK | L24: =ISNUMBER(J24) -> TRUE | M24: Cash on Delivery | N24: Returned | O24: 0 | P24: =IF(AND(O24<0,O24<>N40),"ERORR","OK") -> OK
A25: 136 | B25: Customer_136 | C25: ORD-20985 | D25: 45820 | E25: Headphones | F25: =VLOOKUP(E25,Mapping!$A$1:$B$20,2,FALSE) -> Electronics | G25: 1 | H25: =IF(AND(G25<0,G25<>$N$4),"ERORR","OK") -> OK | I25: =ISNUMBER(G25) -> TRUE | J25: 696.71 | K25: =IF(OR(Table1[[#This Row],[Price]]>$S$20,Table1[[#This Row],[Price]]<$T$19),"Outlier","OK") -> OK | L25: =ISNUMBER(J25) -> TRUE | M25: Credit Card | N25: Delivered | O25: =Table1[[#This Row],[Price]]*Table1[[#This Row],[Quantity]] -> 696.71 | P25: =IF(AND(O25<0,O25<>N42),"ERORR","OK") -> OK
A26: 152 | B26: Customer_152 | C26: ORD-72869 | D26: 45922 | E26: Lamp | F26: =VLOOKUP(E26,Mapping!$A$1:$B$20,2,FALSE) -> Home | G26: 3 | H26: =IF(AND(G26<0,G26<>$N$4),"ERORR","OK") -> OK | I26: =ISNUMBER(G26) -> TRUE | J26: 233.11 | K26: =IF(OR(Table1[[#This Row],[Price]]>$S$20,Table1[[#This Row],[Price]]<$T$19),"Outlier","OK") -> OK | L26: =ISNUMBER(J26) -> TRUE | M26: PayPal | N26: Returned | O26: 0 | P26: =IF(AND(O26<0,O26<>N43),"ERORR","OK") -> OK
A27: 163 | B27: Customer_163 | C27: ORD-24378 | D27: 44931 | E27: Smartwatch | F27: =VLOOKUP(E27,Mapping!$A$1:$B$20,2,FALSE) -> Electronics | G27: 3 | H27: =IF(AND(G27<0,G27<>$N$4),"ERORR","OK") -> OK | I27: =ISNUMBER(G27) -> TRUE | J27: 235.26 | K27: =IF(OR(Table1[[#This Row],[Price]]>$S$20,Table1[[#This Row],[Price]]<$T$19),"Outlier","OK") -> OK | L27: =ISNUMBER(J27) -> TRUE | M27: Cash on Delivery | N27: Shipped | O27: =Table1[[#This Row],[Price]]*Table1[[#This Row],[Quantity]] -> 705.78 | P27: =IF(AND(O27<0,O27<>N44),"ERORR","OK") -> OK
A28: 174 | B28: Customer_174 | C28: ORD-16766 | D28: 45920 | E28: Microwave | F28: =VLOOKUP(E28,Mapping!$A$1:$B$20,2,FALSE) -> Home | G28: 4 | H28: =IF(AND(G28<0,G28<>$N$4),"ERORR","OK") -> OK | I28: =ISNUMBER(G28) -> TRUE | J28: 187.48 | K28: =IF(OR(Table1[[#This Row],[Price]]>$S$20,Table1[[#This Row],[Price]]<$T$19),"Outlier","OK") -> OK | L28: =ISNUMBER(J28) -> TRUE | M28: Credit Card | N28: Returned | O28: 0 | P28: =IF(AND(O28<0,O28<>N45),"ERORR","OK") -> OK
A29: 189 | B29: Customer_189 | C29: ORD-30627 | D29: 45883 | E29: Lamp | F29: =VLOOKUP(E29,Mapping!$A$1:$B$20,2,FALSE) -> Home | G29: 1 | H29: =IF(AND(G29<0,G29<>$N$4),"ERORR","OK") -> OK | I29: =ISNUMBER(G29) -> TRUE | J29: 814.68 | K29: =IF(OR(Table1[[#This Row],[Price]]>$S$20,Table1[[#This Row],[Price]]<$T$19),"Outlier","OK") -> OK | L29: =ISNUMBER(J29) -> TRUE | M29: Cash on Delivery | N29: Returned | O29: 0 | P29: =IF(AND(O29<0,O29<>N46),"ERORR","OK") -> OK
A30: 114 | B30: Customer_114 | C30: ORD-77417 | D30: 44931 | E30: Smartphone | F30: =VLOOKUP(E30,Mapping!$A$1:$B$20,2,FALSE) -> Electronics | G30: 2 | H30: =IF(AND(G30<0,G30<>$N$4),"ERORR","OK") -> OK | I30: =ISNUMBER(G30) -> TRUE | J30: 413.13 | K30: =IF(OR(Table1[[#This Row],[Price]]>$S$20,Table1[[#This Row],[Price]]<$T$19),"Outlier","OK") -> OK | L30: =ISNUMBER(J30) -> TRUE | M30: Cash on Delivery | N30: Shipped | O30: =Table1[[#This Row],[Price]]*Table1[[#This Row],[Quantity]] -> 826.26 | P30: =IF(AND(O30<0,O30<>N47),"ERORR","OK") -> OK
A31: 180 | B31: Customer_180 | C31: ORD-86629 | D31: 45742 | E31: Laptop | F31: =VLOOKUP(E31,Mapping!$A$1:$B$20,2,FALSE) -> Electronics | G31: 2 | H31: =IF(AND(G31<0,G31<>$N$4),"ERORR","OK") -> OK | I31: =ISNUMBER(G31) -> TRUE | J31: 418.38 | K31: =IF(OR(Table1[[#This Row],[Price]]>$S$20,Table1[[#This Row],[Price]]<$T$19),"Outlier","OK") -> OK | L31: =ISNUMBER(J31) -> TRUE | M31: Credit Card | N31: Processing | O31: =Table1[[#This Row],[Price]]*Table1[[#This Row],[Quantity]] -> 836.76 | P31: =IF(AND(O31<0,O31<>N47),"ERORR","OK") -> OK
A32: 161 | B32: Customer_161 | C32: ORD-27653 | D32: 45641 | E32: Science | F32: =VLOOKUP(E32,Mapping!$A$1:$B$20,2,FALSE) -> Books | G32: 4 | H32: =IF(AND(G32<0,G32<>$N$4),"ERORR","OK") -> OK | I32: =ISNUMBER(G32) -> TRUE | J32: 209.32 | K32: =IF(OR(Table1[[#This Row],[Price]]>$S$20,Table1[[#This Row],[Price]]<$T$19),"Outlier","OK") -> OK | L32: =ISNUMBER(J32) -> TRUE | M32: Bank Transfer | N32: Shipped | O32: =Table1[[#This Row],[Price]]*Table1[[#This Row],[Quantity]] -> 837.28 | P32: =IF(AND(O32<0,O32<>N47),"ERORR","OK") -> OK
A33: 109 | B33: Customer_109 | C33: ORD-18512 | D33: 45780 | E33: Tennis Racket | F33: =VLOOKUP(E33,Mapping!$A$1:$B$20,2,FALSE) -> Sports | G33: 5 | H33: =IF(AND(G33<0,G33<>$N$4),"ERORR","OK") -> OK | I33: =ISNUMBER(G33) -> TRUE | J33: 168.34 | K33: =IF(OR(Table1[[#This Row],[Price]]>$S$20,Table1[[#This Row],[Price]]<$T$19),"Outlier","OK") -> OK | L33: =ISNUMBER(J33) -> TRUE | M33: Credit Card | N33: Shipped | O33: =Table1[[#This Row],[Price]]*Table1[[#This Row],[Quantity]] -> 841.7 | P33: =IF(AND(O33<0,O33<>Table1[[#This Row],[Status]]),"ERORR","OK") -> OK
A34: 165 | B34: Customer_165 | C34: ORD-55695 | D34: 45604 | E34: Shoes | F34: =VLOOKUP(E34,Mapping!$A$1:$B$20,2,FALSE) -> Clothings | G34: 2 | H34: =IF(AND(G34<0,G34<>$N$4),"ERORR","OK") -> OK | I34: =ISNUMBER(G34) -> TRUE | J34: 645 | K34: =IF(OR(Table1[[#This Row],[Price]]>$S$20,Table1[[#This Row],[Price]]<$T$19),"Outlier","OK") -> OK | L34: =ISNUMBER(J34) -> TRUE | M34: Credit Card | N34: Delivered | O34: =Table1[[#This Row],[Price]]*Table1[[#This Row],[Quantity]] -> 1290 | P34: =IF(AND(O34<0,O34<>N50),"ERORR","OK") -> OK
A35: 190 | B35: Customer_190 | C35: ORD-38469 | D35: 45837 | E35: Vacuum | F35: =VLOOKUP(E35,Mapping!$A$1:$B$20,2,FALSE) -> Home | G35: 1 | H35: =IF(AND(G35<0,G35<>$N$4),"ERORR","OK") -> OK | I35: =ISNUMBER(G35) -> TRUE | J35: 920.37 | K35: =IF(OR(Table1[[#This Row],[Price]]>$S$20,Table1[[#This Row],[Price]]<$T$19),"Outlier","OK") -> OK | L35: =ISNUMBER(J35) -> TRUE | M35: Bank Transfer | N35: Processing | O35: =Table1[[#This Row],[Price]]*Table1[[#This Row],[Quantity]] -> 920.37 | P35: =IF(AND(O35<0,O35<>N50),"ERORR","OK") -> OK
A36: 158 | B36: Customer_158 | C36: ORD-35817 | D36: 45752 | E36: Smartwatch | F36: =VLOOKUP(E36,Mapping!$A$1:$B$20,2,FALSE) -> Electronics | G36: 1 | H36: =IF(AND(G36<0,G36<>$N$4),"ERORR","OK") -> OK | I36: =ISNUMBER(G36) -> TRUE | J36: 933.58 | K36: =IF(OR(Table1[[#This Row],[Price]]>$S$20,Table1[[#This Row],[Price]]<$T$19),"Outlier","OK") -> OK | L36: =ISNUMBER(J36) -> TRUE | M36: Cash on Delivery | N36: Shipped | O36: =Table1[[#This Row],[Price]]*Table1[[#This Row],[Quantity]] -> 933.58 | P36: =IF(AND(O36<0,O36<>N51),"ERORR","OK") -> OK
A37: 198 | B37: Customer_198 | C37: ORD-14608 | D37: 45865 | E37: Vacuum | F37: =VLOOKUP(E37,Mapping!$A$1:$B$20,2,FALSE) -> Home | G37: 2 | H37: =IF(AND(G37<0,G37<>$N$4),"ERORR","OK") -> OK | I37: =ISNUMBER(G37) -> TRUE | J37: 497.01 | K37: =IF(OR(Table1[[#This Row],[Price]]>$S$20,Table1[[#This Row],[Price]]<$T$19),"Outlier","OK") -> OK | L37: =ISNUMBER(J37) -> TRUE | M37: Cash on Delivery | N37: Shipped | O37: =Table1[[#This Row],[Price]]*Table1[[#This Row],[Quantity]] -> 994.02 | P37: =IF(AND(O37<0,O37<>N52),"ERORR","OK") -> OK
A38: 185 | B38: Customer_185 | C38: ORD-57123 | D38: 45883 | E38: Football | F38: =VLOOKUP(E38,Mapping!$A$1:$B$20,2,FALSE) -> Sports | G38: 2 | H38: =IF(AND(G38<0,G38<>$N$4),"ERORR","OK") -> OK | I38: =ISNUMBER(G38) -> TRUE | J38: 730.92 | K38: =IF(OR(Table1[[#This Row],[Price]]>$S$20,Table1[[#This Row],[Price]]<$T$19),"Outlier","OK") -> OK | L38: =ISNUMBER(J38) -> TRUE | M38: Cash on Delivery | N38: Cancelled | O38: 0 | P38: =IF(AND(O38<0,O38<>N54),"ERORR","OK") -> OK
A39: 157 | B39: Customer_157 | C39: ORD-34407 | D39: 45967 | E39: Jacket | F39: =VLOOKUP(E39,Mapping!$A$1:$B$20,2,FALSE) -> Clothings | G39: 4 | H39: =IF(AND(G39<0,G39<>$N$4),"ERORR","OK") -> OK | I39: =ISNUMBER(G39) -> TRUE | J39: 275.1 | K39: =IF(OR(Table1[[#This Row],[Price]]>$S$20,Table1[[#This Row],[Price]]<$T$19),"Outlier","OK") -> OK | L39: =ISNUMBER(J39) -> TRUE | M39: Bank Transfer | N39: Processing | O39: =Table1[[#This Row],[Price]]*Table1[[#This Row],[Quantity]] -> 1100.4 | P39: =IF(AND(O39<0,O39<>N55),"ERORR","OK") -> OK
A40: 122 | B40: Customer_122 | C40: ORD-21443 | D40: 45793 | E40: Microwave | F40: =VLOOKUP(E40,Mapping!$A$1:$B$20,2,FALSE) -> Home | G40: 2 | H40: =IF(AND(G40<0,G40<>$N$4),"ERORR","OK") -> OK | I40: =ISNUMBER(G40) -> TRUE | J40: 556.93 | K40: =IF(OR(Table1[[#This Row],[Price]]>$S$20,Table1[[#This Row],[Price]]<$T$19),"Outlier","OK") -> OK | L40: =ISNUMBER(J40) -> TRUE | M40: PayPal | N40: Shipped | O40: =Table1[[#This Row],[Price]]*Table1[[#This Row],[Quantity]] -> 1113.86 | P40: =IF(AND(O40<0,O40<>N55),"ERORR","OK") -> OK
...

Sheet Mapping
A1: Smartwatch | B1: Electronics | D1: Customer_Name
A2: Smartphone | B2: Electronics | D2: Customer_163
A3: Laptop | B3: Electronics | D3: Customer_114
A4: Shoes | B4: Clothings | D4: Customer_145
A5: Lamp | B5: Home | D5: Customer_165
A6: Comics | B6: Books | D6: Customer_128
A7: Microwave | B7: Home | D7: Customer_172
A8: Tennis Racket | B8: Sports | D8: Customer_187
A9: Blender | B9: Home | D9: Customer_188
A10: Yoga Mat | B10: Sports | D10: Customer_105
A11: Jeans | B11: Clothings | D11: Customer_100
A12: Biography | B12: Books | D12: Customer_150
... A20: T-shirt | B20: Clothings | D20: Customer_160
D21: Customer_115
D22: Customer_199
D23: Customer_144
D24: Customer_106
D25: Customer_125
D26: Customer_135
D27: Customer_139
D28: Customer_164
D29: Customer_194
D30: Customer_117
D31: Customer_141
D32: Customer_184
... D93: Customer_157

Sheet Backup of Raw Data
A1: ID | B1: Customer_Name | C1: Order_ID | D1: Order_Date | E1: Order_Date | F1: Order_Date | G1: Product | H1: Category | I1: Quantity | J1: Price | L1: Payment_Method | M1: Status | N1: Total | O1: Q1 | P1: =_xlfn.QUARTILE.INC(F:F,1) -> 45697
A2: 163 | B2: Customer_163 | C2: ORD-24378 | D2: 44931 | E2: =ISNUMBER(D2) -> TRUE | F2: 44931 | G2: Smartwatch | H2: Electronics | I2: 3 | J2: 235.26 | L2: Cash on Delivery | M2: Shipped | N2: 705.78 | O2: q3 | P2: =_xlfn.QUARTILE.INC(F:F,3) -> 45875
A3: 114 | B3: Customer_114 | C3: ORD-77417 | D3: 44931 | E3: =ISNUMBER(D3) -> TRUE | F3: =DATE(RIGHT(D3,4),MONTH(1&LEFT(D3,3)),MID(D3,5,2)) -> 1107386 | G3: Smartphone | H3: Electronics | I3: 2 | J3: 413.13 | L3: Cash on Delivery | M3: Shipped | N3: 826.26 | O3: IQR | P3: =P2-P1 -> 178
A4: 145 | B4: Customer_145 | C4: ORD-75314 | D4: 45047 | E4: =ISNUMBER(D4) -> TRUE | F4: 45047 | G4: Laptop | H4: Electronics | I4: 2 | J4: 860.99 | L4: Bank Transfer | M4: Returned | N4: 1721.98 | O4: Lower | P4: =P1-(1.5*P3) -> 45430 | Q4: =ABS(P4) -> 45430
A5: 165 | B5: Customer_165 | C5: ORD-55695 | D5: 45604 | E5: =ISNUMBER(D5) -> TRUE | F5: 45604 | G5: Shoes | H5: Clothing | I5: 2 | J5: 443.13 | L5: Credit Card | M5: Delivered | N5: 886.26 | O5: Upper | P5: =P2+1.5*P3 -> 46142
A6: 128 | B6: Customer_128 | C6: ORD-12270 | D6: 45606 | E6: =ISNUMBER(D6) -> TRUE | F6: 45606 | G6: Lamp | H6: electronics | I6: 3 | J6: 898.69 | L6: Bank Transfer | M6: Delivered | N6: 2696.07
A7: 172 | B7: Customer_172 | C7: ORD-48008 | D7: 45614 | E7: =ISNUMBER(D7) -> TRUE | F7: 45614 | G7: Comics | H7: Books | I7: 2 | J7: 942.76 | L7: Bank Transfer | M7: Returned | N7: 1885.52
A8: 187 | B8: Customer_187 | C8: ORD-41292 | D8: 45615 | E8: =ISNUMBER(D8) -> TRUE | F8: 45615 | G8: Smartphone | H8: Electronics | I8: 3 | J8: 882.96 | L8: Bank Transfer | M8: Returned | N8: 2648.88
A9: 188 | B9: Customer_188 | C9: ORD-58590 | D9: 45615 | E9: =ISNUMBER(D9) -> TRUE | F9: 45615 | G9: Microwave | H9: Home | I9: 5 | J9: 504.05 | L9: Cash on Delivery | M9: Shipped | N9: 2520.25
A10: 105 | B10: Customer_105 | C10: ORD-22442 | D10: 45616 | E10: =ISNUMBER(D10) -> TRUE | F10: 45616 | G10: Tennis Racket | H10: Sports | I10: 3 | J10: 122.06 | L10: Cash on Delivery | M10: Cancelled | N10: 366.18
A11: 100 | B11: Customer_100 | C11: ORD-41285 | D11: 45618 | E11: =ISNUMBER(D11) -> TRUE | F11: 45618 | G11: Blender | H11: Home | I11: 3 | J11: 38 | L11: Cash on Delivery | M11: Shipped | N11: 114
A12: 150 | B12: Customer_150 | C12: ORD-76902 | D12: 45623 | E12: =ISNUMBER(D12) -> TRUE | F12: 45623 | G12: Yoga Mat | H12: Sports | I12: 1 | J12: 206.19 | L12: Credit Card | M12: Returned | N12: 206.19
A13: 156 | B13: Customer_156 | C13: ORD-34679 | D13: 45624 | E13: =ISNUMBER(D13) -> TRUE | F13: 45624 | G13: Jeans | H13: Clothing | I13: 2 | L13: Bank Transfer | M13: Shipped
A14: 133 | B14: Customer_133 | C14: ORD-68182 | D14: 45631 | E14: =ISNUMBER(D14) -> TRUE | F14: 45631 | G14: Biography | H14: nan | I14: 5 | J14: 343.24 | L14: Credit Card | M14: Shipped | N14: 1716.2
A15: 171 | B15: Customer_171 | C15: ORD-99790 | D15: 45632 | E15: =ISNUMBER(D15) -> TRUE | F15: 45632 | G15: Shoes | H15: Clothing | I15: 3 | J15: 688.68 | L15: PayPal | M15: Processing | N15: 2066.04
A16: 161 | B16: Customer_161 | C16: ORD-27653 | D16: 45641 | E16: =ISNUMBER(D16) -> TRUE | F16: 45641 | G16: Science | H16: Books | I16: 4 | J16: 209.32 | L16: Bank Transfer | M16: Shipped | N16: 837.28
A17: 119 | B17: Customer_119 | C17: ORD-76016 | D17: 45645 | E17: =ISNUMBER(D17) -> TRUE | F17: 45645 | G17: Basketball | H17: Sports | I17: 4 | J17: 438.19 | L17: Cash on Delivery | M17: Processing | N17: 1752.76
A18: 102 | B18: Customer_102 | C18: ORD-84355 | D18: 45649 | E18: =ISNUMBER(D18) -> TRUE | F18: 45649 | G18: Tennis Racket | H18: Sports | I18: 1 | J18: 389.05 | L18: PayPal | M18: Delivered | N18: 389.05
A19: 196 | B19: Customer_196 | C19: ORD-78384 | D19: 45649 | E19: =ISNUMBER(D19) -> TRUE | F19: 45649 | G19: Vacuum | H19: Home | J19: abd | L19: PayPal | M19: Delivered
A20: 181 | B20: Customer_181 | C20: ORD-54481 | D20: 45655 | E20: =ISNUMBER(D20) -> TRUE | F20: 45655 | G20: Smartphone | H20: nan | I20: 1 | J20: 266.48 | L20: Cash on Delivery | M20: Cancelled | N20: 266.48
A21: 107 | B21: Customer_107 | C21: ORD-89122 | D21: 45660 | E21: =ISNUMBER(D21) -> TRUE | F21: 45660 | G21: Biography | H21: Books | I21: 5 | J21: 587.68 | L21: PayPal | M21: Returned | N21: 2938.4
A22: 160 | B22: Customer_160 | C22: ORD-96037 | D22: 45660 | E22: =ISNUMBER(D22) -> TRUE | F22: 45660 | G22: Science | H22: Books | I22: 5 | J22: 242.52 | L22: Cash on Delivery | M22: Returned | N22: 1212.6
A23: 115 | B23: Customer_115 | C23: ORD-72778 | D23: 45667 | E23: =ISNUMBER(D23) -> TRUE | F23: 45667 | G23: Fiction | H23: Books | I23: 2 | J23: 796.84 | L23: Cash on Delivery | M23: Returned | N23: 1115.576
A24: 199 | B24: Customer_199 | C24: ORD-82922 | D24: 45679 | E24: =ISNUMBER(D24) -> TRUE | F24: 45679 | G24: Blender | H24: Home | I24: 5 | J24: 372.28 | L24: Credit Card | M24: Shipped | N24: 1861.4
A25: 144 | B25: Customer_144 | C25: ORD-89452 | D25: 45684 | E25: =ISNUMBER(D25) -> TRUE | F25: 45684 | G25: Football | H25: Sports | I25: 5 | J25: 849.07 | L25: Bank Transfer | M25: Processing | N25: 4245.35
A26: 106 | B26: Customer_106 | C26: ORD-25885 | D26: 45690 | E26: =ISNUMBER(D26) -> TRUE | F26: 45690 | G26: Blender | H26: Home | J26: 978.63 | L26: Bank Transfer | M26: Processing
A27: 125 | B27: Customer_125 | C27: ORD-23202 | D27: 45697 | E27: =ISNUMBER(D27) -> TRUE | F27: 45697 | G27: Comics | H27: Books | I27: 4 | J27: 765.69 | L27: PayPal | M27: Shipped | N27: 3062.76
A28: 135 | B28: Customer_135 | C28: ORD-33656 | D28: 45697 | E28: =ISNUMBER(D28) -> TRUE | F28: 45697 | G28: Smartwatch | H28: electronics | I28: 4 | J28: 446.19 | L28: Cash on Delivery | M28: Cancelled | N28: 1784.76
A29: 139 | B29: Customer_139 | C29: ORD-38418 | D29: 45697 | E29: =ISNUMBER(D29) -> TRUE | F29: 45697 | G29: Smartphone | H29: Electronics | I29: 2 | J29: 681.38 | L29: Credit Card | M29: Cancelled | N29: 1362.76
A30: 164 | B30: Customer_164 | C30: ORD-23010 | D30: 45697 | E30: =ISNUMBER(D30) -> TRUE | F30: 45697 | G30: Tennis Racket | H30: Sports | J30: 587.64 | L30: Credit Card | M30: Returned
A31: 194 | B31: Customer_194 | C31: ORD-69764 | D31: 45698 | E31: =ISNUMBER(D31) -> TRUE | F31: 45698 | G31: Lamp | H31: Home | I31: 5 | J31: 944.54 | L31: Cash on Delivery | M31: Returned | N31: 4722.7
A32: 117 | B32: Customer_117 | C32: ORD-72751 | D32: 45700 | E32: =ISNUMBER(D32) -> TRUE | F32: 45700 | G32: Blender | H32: electronic | I32: -2 | J32: 10000 | L32: Cash on Delivery | M32: Processing | N32: -20000
A33: 141 | B33: Customer_141 | C33: ORD-45059 | D33: 45701 | E33: =ISNUMBER(D33) -> TRUE | F33: 45701 | G33: Fiction | H33: Books | I33: 3 | J33: 546.04 | L33: Cash on Delivery | M33: Returned | N33: 1638.12
A34: 184 | B34: Customer_184 | C34: ORD-67799 | D34: 45703 | E34: =ISNUMBER(D34) -> TRUE | F34: 45703 | G34: Jeans | I34: 4 | J34: 101.19 | L34: Bank Transfer | M34: Processing | N34: 404.76
A35: 154 | B35: Customer_154 | C35: ORD-95990 | D35: 45709 | E35: =ISNUMBER(D35) -> TRUE | F35: 45709 | G35: Blender | H35: Home | I35: 5 | J35: 789.64 | L35: Cash on Delivery | M35: Cancelled | N35: 3948.2
A36: 137 | B36: Customer_137 | C36: ORD-91254 | D36: 45711 | E36: =ISNUMBER(D36) -> TRUE | F36: 45711 | G36: Vacuum | H36: Home | I36: 3 | J36: -100 | L36: Cash on Delivery | M36: Delivered | N36: -300
A37: 175 | B37: Customer_175 | C37: ORD-56651 | D37: 45712 | E37: =ISNUMBER(D37) -> TRUE | F37: 45712 | G37: Headphones | H37: Electronics | I37: 1 | J37: 111.36 | L37: Credit Card | M37: Processing | N37: 111.36
A38: 175 | B38: Customer_175 | C38: ORD-56651 | D38: 45712 | E38: =ISNUMBER(D38) -> TRUE | F38: 45712 | G38: Headphones | H38: Electronics | I38: 1 | J38: 111.36 | L38: Credit Card | M38: Processing | N38: 77.952
A39: 140 | B39: Customer_140 | C39: ORD-67096 | D39: 45714 | E39: =ISNUMBER(D39) -> TRUE | F39: 45714 | G39: Fiction | H39: Books | I39: 4 | J39: 588.98 | L39: Credit Card | M39: Returned | N39: 2355.92
A40: 112 | B40: Customer_112 | C40: ORD-80867 | D40: 45718 | E40: =ISNUMBER(D40) -> TRUE | F40: 45718 | G40: Shoes | H40: Clothing | I40: 4 | J40: 752.13 | L40: Bank Transfer | M40: Delivered | N40: 3008.52
...
